\doxysection{pandas.\+errors.\+Merge\+Error Class Reference}
\hypertarget{classpandas_1_1errors_1_1MergeError}{}\label{classpandas_1_1errors_1_1MergeError}\index{pandas.errors.MergeError@{pandas.errors.MergeError}}


Inheritance diagram for pandas.\+errors.\+Merge\+Error\+:
% FIG 0


Collaboration diagram for pandas.\+errors.\+Merge\+Error\+:
% FIG 1


\doxysubsection{Detailed Description}
\begin{DoxyVerb}Exception raised when merging data.

Subclass of ``ValueError``.

Examples
--------
>>> left = pd.DataFrame({"a": ["a", "b", "b", "d"],
...                     "b": ["cat", "dog", "weasel", "horse"]},
...                     index=range(4))
>>> right = pd.DataFrame({"a": ["a", "b", "c", "d"],
...                      "c": ["meow", "bark", "chirp", "nay"]},
...                      index=range(4)).set_index("a")
>>> left.join(right, on="a", validate="one_to_one",)
Traceback (most recent call last):
MergeError: Merge keys are not unique in left dataset; not a one-to-one merge
\end{DoxyVerb}
 

Definition at line \mbox{\hyperlink{pandas_2errors_2____init_____8py_source_l00253}{253}} of file \mbox{\hyperlink{pandas_2errors_2____init_____8py_source}{\+\_\+\+\_\+init\+\_\+\+\_\+.\+py}}.



The documentation for this class was generated from the following file\+:\begin{DoxyCompactItemize}
\item 
/home/jam/\+Research/\+IRES-\/2025/dev/src/llm-\/scripts/testing/hypothesis-\/testing/hyp-\/env/lib/python3.\+12/site-\/packages/pandas/errors/\+\_\+\+\_\+init\+\_\+\+\_\+.\+py\end{DoxyCompactItemize}
