\doxysection{numpy.\+testing.\+\_\+private.\+utils.\+Known\+Failure\+Exception Class Reference}
\hypertarget{classnumpy_1_1testing_1_1__private_1_1utils_1_1KnownFailureException}{}\label{classnumpy_1_1testing_1_1__private_1_1utils_1_1KnownFailureException}\index{numpy.testing.\_private.utils.KnownFailureException@{numpy.testing.\_private.utils.KnownFailureException}}


Inheritance diagram for numpy.\+testing.\+\_\+private.\+utils.\+Known\+Failure\+Exception\+:
% FIG 0


Collaboration diagram for numpy.\+testing.\+\_\+private.\+utils.\+Known\+Failure\+Exception\+:
% FIG 1


\doxysubsection{Detailed Description}
\begin{DoxyVerb}Raise this exception to mark a test as a known failing test.\end{DoxyVerb}
 

Definition at line \mbox{\hyperlink{numpy_2testing_2__private_2utils_8py_source_l00045}{45}} of file \mbox{\hyperlink{numpy_2testing_2__private_2utils_8py_source}{utils.\+py}}.



The documentation for this class was generated from the following file\+:\begin{DoxyCompactItemize}
\item 
/home/jam/\+Research/\+IRES-\/2025/dev/src/llm-\/scripts/testing/hypothesis-\/testing/hyp-\/env/lib/python3.\+12/site-\/packages/numpy/testing/\+\_\+private/utils.\+py\end{DoxyCompactItemize}
